Traceback (most recent call last):
  File "/usr/local/lib/python3.10/site-packages/urllib3/connectionpool.py", line 449, in _make_request
    six.raise_from(e, None)
  File "<string>", line 3, in raise_from
  File "/usr/local/lib/python3.10/site-packages/urllib3/connectionpool.py", line 444, in _make_request
    httplib_response = conn.getresponse()
  File "/usr/local/lib/python3.10/http/client.py", line 1374, in getresponse
    response.begin()
  File "/usr/local/lib/python3.10/http/client.py", line 318, in begin
    version, status, reason = self._read_status()
  File "/usr/local/lib/python3.10/http/client.py", line 279, in _read_status
    line = str(self.fp.readline(_MAXLINE + 1), "iso-8859-1")
  File "/usr/local/lib/python3.10/socket.py", line 705, in readinto
    return self._sock.recv_into(b)
  File "/usr/local/lib/python3.10/ssl.py", line 1274, in recv_into
    return self.read(nbytes, buffer)
  File "/usr/local/lib/python3.10/ssl.py", line 1130, in read
    return self._sslobj.read(len, buffer)
TimeoutError: The read operation timed out

During handling of the above exception, another exception occurred:

Traceback (most recent call last):
  File "/usr/local/lib/python3.10/site-packages/requests/adapters.py", line 489, in send
    resp = conn.urlopen(
  File "/usr/local/lib/python3.10/site-packages/urllib3/connectionpool.py", line 785, in urlopen
    retries = retries.increment(
  File "/usr/local/lib/python3.10/site-packages/urllib3/util/retry.py", line 550, in increment
    raise six.reraise(type(error), error, _stacktrace)
  File "/usr/local/lib/python3.10/site-packages/urllib3/packages/six.py", line 770, in reraise
    raise value
  File "/usr/local/lib/python3.10/site-packages/urllib3/connectionpool.py", line 703, in urlopen
    httplib_response = self._make_request(
  File "/usr/local/lib/python3.10/site-packages/urllib3/connectionpool.py", line 451, in _make_request
    self._raise_timeout(err=e, url=url, timeout_value=read_timeout)
  File "/usr/local/lib/python3.10/site-packages/urllib3/connectionpool.py", line 340, in _raise_timeout
    raise ReadTimeoutError(
urllib3.exceptions.ReadTimeoutError: HTTPSConnectionPool(host='api.telegram.org', port=443): Read timed out. (read timeout=25)

During handling of the above exception, another exception occurred:

Traceback (most recent call last):
  File "/home/jzjpzbsi/resp.py", line 92, in <module>
    bot.polling()
  File "/home/jzjpzbsi/.local/lib/python3.10/site-packages/telebot/__init__.py", line 1043, in polling
    self.__threaded_polling(non_stop=non_stop, interval=interval, timeout=timeout, long_polling_timeout=long_polling_timeout,
  File "/home/jzjpzbsi/.local/lib/python3.10/site-packages/telebot/__init__.py", line 1118, in __threaded_polling
    raise e
  File "/home/jzjpzbsi/.local/lib/python3.10/site-packages/telebot/__init__.py", line 1073, in __threaded_polling
    polling_thread.raise_exceptions()
  File "/home/jzjpzbsi/.local/lib/python3.10/site-packages/telebot/util.py", line 108, in raise_exceptions
    raise self.exception_info
  File "/home/jzjpzbsi/.local/lib/python3.10/site-packages/telebot/util.py", line 90, in run
    task(*args, **kwargs)
  File "/home/jzjpzbsi/.local/lib/python3.10/site-packages/telebot/__init__.py", line 649, in __retrieve_updates
    updates = self.get_updates(offset=(self.last_update_id + 1), 
  File "/home/jzjpzbsi/.local/lib/python3.10/site-packages/telebot/__init__.py", line 623, in get_updates
    json_updates = apihelper.get_updates(self.token, offset, limit, timeout, allowed_updates, long_polling_timeout)
  File "/home/jzjpzbsi/.local/lib/python3.10/site-packages/telebot/apihelper.py", line 321, in get_updates
    return _make_request(token, method_url, params=payload)
  File "/home/jzjpzbsi/.local/lib/python3.10/site-packages/telebot/apihelper.py", line 156, in _make_request
    result = _get_req_session().request(
  File "/usr/local/lib/python3.10/site-packages/requests/sessions.py", line 587, in request
    resp = self.send(prep, **send_kwargs)
  File "/usr/local/lib/python3.10/site-packages/requests/sessions.py", line 701, in send
    r = adapter.send(request, **kwargs)
  File "/usr/local/lib/python3.10/site-packages/requests/adapters.py", line 578, in send
    raise ReadTimeout(e, request=request)
requests.exceptions.ReadTimeout: HTTPSConnectionPool(host='api.telegram.org', port=443): Read timed out. (read timeout=25)
